2024-12-22 16:45:17,256 - ERROR - 处理帧时出错: Invalid model_name passed - face_detector/yolov11
2024-12-22 16:45:17,723 - ERROR - 处理帧时出错: Invalid model_name passed - face_detector/yolov11
2024-12-22 16:45:17,851 - ERROR - 处理帧时出错: Invalid model_name passed - face_detector/yolov11
2024-12-22 16:45:18,060 - ERROR - 处理帧时出错: Invalid model_name passed - face_detector/yolov11
2024-12-22 16:45:18,188 - ERROR - 处理帧时出错: Invalid model_name passed - face_detector/yolov11
2024-12-22 16:45:18,363 - ERROR - 处理帧时出错: Invalid model_name passed - face_detector/yolov11
2024-12-22 16:45:18,523 - ERROR - 处理帧时出错: Invalid model_name passed - face_detector/yolov11
2024-12-22 16:45:18,699 - ERROR - 处理帧时出错: Invalid model_name passed - face_detector/yolov11
2024-12-22 16:45:18,875 - ERROR - 处理帧时出错: Invalid model_name passed - face_detector/yolov11
2024-12-22 16:45:19,035 - ERROR - 处理帧时出错: Invalid model_name passed - face_detector/yolov11
2024-12-22 16:45:19,211 - ERROR - 处理帧时出错: Invalid model_name passed - face_detector/yolov11
2024-12-22 16:45:19,371 - ERROR - 处理帧时出错: Invalid model_name passed - face_detector/yolov11
2024-12-22 16:45:22,331 - ERROR - 处理帧时出错: Invalid model_name passed - face_detector/yolov11
2024-12-22 16:45:22,492 - ERROR - 处理帧时出错: Invalid model_name passed - face_detector/yolov11
2024-12-22 16:45:22,668 - ERROR - 处理帧时出错: Invalid model_name passed - face_detector/yolov11
2024-12-22 16:45:22,828 - ERROR - 处理帧时出错: Invalid model_name passed - face_detector/yolov11
2024-12-22 16:45:23,004 - ERROR - 处理帧时出错: Invalid model_name passed - face_detector/yolov11
2024-12-22 16:45:23,401 - ERROR - 处理帧时出错: Invalid model_name passed - face_detector/yolov11
2024-12-22 16:45:23,549 - ERROR - 处理帧时出错: Invalid model_name passed - face_detector/yolov11
2024-12-22 16:45:23,708 - ERROR - 处理帧时出错: Invalid model_name passed - face_detector/yolov11
2024-12-22 16:45:23,853 - ERROR - 处理帧时出错: Invalid model_name passed - face_detector/yolov11
2024-12-22 16:45:24,061 - ERROR - 处理帧时出错: Invalid model_name passed - face_detector/yolov11
2024-12-22 16:45:24,189 - ERROR - 处理帧时出错: Invalid model_name passed - face_detector/yolov11
2024-12-22 16:45:24,379 - ERROR - 处理帧时出错: Invalid model_name passed - face_detector/yolov11
2024-12-22 16:45:24,524 - ERROR - 处理帧时出错: Invalid model_name passed - face_detector/yolov11
2024-12-22 16:45:24,700 - ERROR - 处理帧时出错: Invalid model_name passed - face_detector/yolov11
2024-12-22 16:45:24,861 - ERROR - 处理帧时出错: Invalid model_name passed - face_detector/yolov11
2024-12-22 16:45:25,036 - ERROR - 处理帧时出错: Invalid model_name passed - face_detector/yolov11
2024-12-22 16:45:25,213 - ERROR - 处理帧时出错: Invalid model_name passed - face_detector/yolov11
2024-12-22 16:45:25,372 - ERROR - 处理帧时出错: Invalid model_name passed - face_detector/yolov11
2024-12-22 16:45:25,548 - ERROR - 处理帧时出错: Invalid model_name passed - face_detector/yolov11
2024-12-22 16:45:25,708 - ERROR - 处理帧时出错: Invalid model_name passed - face_detector/yolov11
2024-12-22 16:45:25,852 - ERROR - 处理帧时出错: Invalid model_name passed - face_detector/yolov11
2024-12-22 16:45:26,063 - ERROR - 处理帧时出错: Invalid model_name passed - face_detector/yolov11
2024-12-22 16:45:26,189 - ERROR - 处理帧时出错: Invalid model_name passed - face_detector/yolov11
2024-12-22 16:45:26,384 - ERROR - 处理帧时出错: Invalid model_name passed - face_detector/yolov11
2024-12-22 16:45:26,524 - ERROR - 处理帧时出错: Invalid model_name passed - face_detector/yolov11
2024-12-22 16:45:26,701 - ERROR - 处理帧时出错: Invalid model_name passed - face_detector/yolov11
2024-12-22 16:45:26,861 - ERROR - 处理帧时出错: Invalid model_name passed - face_detector/yolov11
2024-12-22 16:45:27,036 - ERROR - 处理帧时出错: Invalid model_name passed - face_detector/yolov11
2024-12-22 16:45:27,212 - ERROR - 处理帧时出错: Invalid model_name passed - face_detector/yolov11
2024-12-22 16:45:27,372 - ERROR - 处理帧时出错: Invalid model_name passed - face_detector/yolov11
2024-12-22 16:45:27,548 - ERROR - 处理帧时出错: Invalid model_name passed - face_detector/yolov11
2024-12-22 16:45:27,708 - ERROR - 处理帧时出错: Invalid model_name passed - face_detector/yolov11
2024-12-22 16:45:27,852 - ERROR - 处理帧时出错: Invalid model_name passed - face_detector/yolov11
2024-12-22 16:45:28,061 - ERROR - 处理帧时出错: Invalid model_name passed - face_detector/yolov11
2024-12-22 16:45:28,189 - ERROR - 处理帧时出错: Invalid model_name passed - face_detector/yolov11
2024-12-22 16:45:28,382 - ERROR - 处理帧时出错: Invalid model_name passed - face_detector/yolov11
2024-12-22 16:45:28,525 - ERROR - 处理帧时出错: Invalid model_name passed - face_detector/yolov11
2024-12-22 16:45:28,701 - ERROR - 处理帧时出错: Invalid model_name passed - face_detector/yolov11
2024-12-22 16:45:28,861 - ERROR - 处理帧时出错: Invalid model_name passed - face_detector/yolov11
2024-12-22 16:45:29,036 - ERROR - 处理帧时出错: Invalid model_name passed - face_detector/yolov11
2024-12-22 16:45:29,213 - ERROR - 处理帧时出错: Invalid model_name passed - face_detector/yolov11
2024-12-22 16:45:29,372 - ERROR - 处理帧时出错: Invalid model_name passed - face_detector/yolov11
2024-12-22 16:45:29,548 - ERROR - 处理帧时出错: Invalid model_name passed - face_detector/yolov11
2024-12-22 16:45:29,708 - ERROR - 处理帧时出错: Invalid model_name passed - face_detector/yolov11
2024-12-22 16:45:29,852 - ERROR - 处理帧时出错: Invalid model_name passed - face_detector/yolov11
2024-12-22 16:45:30,061 - ERROR - 处理帧时出错: Invalid model_name passed - face_detector/yolov11
2024-12-22 16:45:30,189 - ERROR - 处理帧时出错: Invalid model_name passed - face_detector/yolov11
2024-12-22 16:45:30,376 - ERROR - 处理帧时出错: Invalid model_name passed - face_detector/yolov11
2024-12-22 16:45:30,525 - ERROR - 处理帧时出错: Invalid model_name passed - face_detector/yolov11
2024-12-22 16:45:30,702 - ERROR - 处理帧时出错: Invalid model_name passed - face_detector/yolov11
2024-12-22 16:45:30,861 - ERROR - 处理帧时出错: Invalid model_name passed - face_detector/yolov11
2024-12-22 16:45:31,036 - ERROR - 处理帧时出错: Invalid model_name passed - face_detector/yolov11
2024-12-22 16:45:31,213 - ERROR - 处理帧时出错: Invalid model_name passed - face_detector/yolov11
2024-12-22 16:45:31,373 - ERROR - 处理帧时出错: Invalid model_name passed - face_detector/yolov11
2024-12-22 16:45:31,549 - ERROR - 处理帧时出错: Invalid model_name passed - face_detector/yolov11
2024-12-22 16:45:31,710 - ERROR - 处理帧时出错: Invalid model_name passed - face_detector/yolov11
2024-12-22 16:45:31,852 - ERROR - 处理帧时出错: Invalid model_name passed - face_detector/yolov11
2024-12-22 16:45:32,061 - ERROR - 处理帧时出错: Invalid model_name passed - face_detector/yolov11
2024-12-22 16:45:32,190 - ERROR - 处理帧时出错: Invalid model_name passed - face_detector/yolov11
2024-12-22 16:45:32,385 - ERROR - 处理帧时出错: Invalid model_name passed - face_detector/yolov11
2024-12-22 16:45:32,524 - ERROR - 处理帧时出错: Invalid model_name passed - face_detector/yolov11
2024-12-22 16:45:32,704 - ERROR - 处理帧时出错: Invalid model_name passed - face_detector/yolov11
2024-12-22 16:45:32,861 - ERROR - 处理帧时出错: Invalid model_name passed - face_detector/yolov11
2024-12-22 16:45:33,036 - ERROR - 处理帧时出错: Invalid model_name passed - face_detector/yolov11
2024-12-22 16:45:33,213 - ERROR - 处理帧时出错: Invalid model_name passed - face_detector/yolov11
2024-12-22 16:45:33,372 - ERROR - 处理帧时出错: Invalid model_name passed - face_detector/yolov11
2024-12-22 16:45:33,549 - ERROR - 处理帧时出错: Invalid model_name passed - face_detector/yolov11
2024-12-22 16:45:33,709 - ERROR - 处理帧时出错: Invalid model_name passed - face_detector/yolov11
2024-12-22 16:45:33,852 - ERROR - 处理帧时出错: Invalid model_name passed - face_detector/yolov11
2024-12-22 16:45:34,061 - ERROR - 处理帧时出错: Invalid model_name passed - face_detector/yolov11
2024-12-22 16:46:09,206 - ERROR - 处理帧时出错: Invalid model_name passed - facial_attribute/Race
2024-12-22 16:46:09,723 - ERROR - 处理帧时出错: Invalid model_name passed - facial_attribute/Race
2024-12-22 16:46:09,995 - ERROR - 处理帧时出错: Invalid model_name passed - facial_attribute/Race
2024-12-22 16:46:10,276 - ERROR - 处理帧时出错: Invalid model_name passed - facial_attribute/Race
2024-12-22 16:46:10,533 - ERROR - 处理帧时出错: Invalid model_name passed - facial_attribute/Race
2024-12-22 16:46:10,797 - ERROR - 处理帧时出错: Invalid model_name passed - facial_attribute/Race
2024-12-22 16:46:11,024 - ERROR - 处理帧时出错: Invalid model_name passed - facial_attribute/Race
2024-12-22 16:46:11,232 - ERROR - 处理帧时出错: Invalid model_name passed - facial_attribute/Race
2024-12-22 16:46:11,476 - ERROR - 处理帧时出错: Invalid model_name passed - facial_attribute/Race
2024-12-22 16:46:11,747 - ERROR - 处理帧时出错: Invalid model_name passed - facial_attribute/Race
2024-12-22 16:46:12,022 - ERROR - 处理帧时出错: Invalid model_name passed - facial_attribute/Race
2024-12-22 16:46:12,301 - ERROR - 处理帧时出错: Invalid model_name passed - facial_attribute/Race
2024-12-22 16:50:05,189 - ERROR - 处理帧时出错: Invalid model_name passed - facial_attribute/Race
2024-12-22 16:50:05,672 - ERROR - 处理帧时出错: Invalid model_name passed - facial_attribute/Race
2024-12-22 16:50:05,938 - ERROR - 处理帧时出错: Invalid model_name passed - facial_attribute/Race
2024-12-22 16:50:06,192 - ERROR - 处理帧时出错: Invalid model_name passed - facial_attribute/Race
2024-12-22 16:50:06,401 - ERROR - 处理帧时出错: Invalid model_name passed - facial_attribute/Race
2024-12-22 16:50:06,619 - ERROR - 处理帧时出错: Invalid model_name passed - facial_attribute/Race
2024-12-22 16:50:06,797 - ERROR - 处理帧时出错: Invalid model_name passed - facial_attribute/Race
2024-12-22 16:50:06,978 - ERROR - 处理帧时出错: Invalid model_name passed - facial_attribute/Race
2024-12-22 16:50:07,248 - ERROR - 处理帧时出错: Invalid model_name passed - facial_attribute/Race
2024-12-22 16:50:07,500 - ERROR - 处理帧时出错: Invalid model_name passed - facial_attribute/Race
2024-12-22 16:50:07,683 - ERROR - 处理帧时出错: Invalid model_name passed - facial_attribute/Race
2024-12-22 16:50:07,952 - ERROR - 处理帧时出错: Invalid model_name passed - facial_attribute/Race
2024-12-22 16:50:08,179 - ERROR - 处理帧时出错: Invalid model_name passed - facial_attribute/Race
2024-12-22 16:50:08,351 - ERROR - 处理帧时出错: Invalid model_name passed - facial_attribute/Race
2024-12-22 16:50:08,523 - ERROR - 处理帧时出错: Invalid model_name passed - facial_attribute/Race
2024-12-22 16:50:08,713 - ERROR - 处理帧时出错: Invalid model_name passed - facial_attribute/Race
2024-12-22 16:50:08,952 - ERROR - 处理帧时出错: Invalid model_name passed - facial_attribute/Race
2024-12-22 16:50:09,241 - ERROR - 处理帧时出错: Invalid model_name passed - facial_attribute/Race
2024-12-22 16:50:09,478 - ERROR - 处理帧时出错: Invalid model_name passed - facial_attribute/Race
2024-12-22 16:50:09,658 - ERROR - 处理帧时出错: Invalid model_name passed - facial_attribute/Race
2024-12-22 16:50:09,932 - ERROR - 处理帧时出错: Invalid model_name passed - facial_attribute/Race
2024-12-22 16:55:02,191 - ERROR - 处理帧时出错: Invalid model_name passed - face_detector/yolov11
2024-12-22 16:55:02,666 - ERROR - 处理帧时出错: Invalid model_name passed - face_detector/yolov11
2024-12-22 16:55:02,795 - ERROR - 处理帧时出错: Invalid model_name passed - face_detector/yolov11
2024-12-22 16:55:03,003 - ERROR - 处理帧时出错: Invalid model_name passed - face_detector/yolov11
2024-12-22 16:55:03,131 - ERROR - 处理帧时出错: Invalid model_name passed - face_detector/yolov11
2024-12-22 16:55:03,306 - ERROR - 处理帧时出错: Invalid model_name passed - face_detector/yolov11
2024-12-22 16:55:03,467 - ERROR - 处理帧时出错: Invalid model_name passed - face_detector/yolov11
2024-12-22 16:55:03,643 - ERROR - 处理帧时出错: Invalid model_name passed - face_detector/yolov11
2024-12-22 16:55:03,818 - ERROR - 处理帧时出错: Invalid model_name passed - face_detector/yolov11
2024-12-22 16:55:03,979 - ERROR - 处理帧时出错: Invalid model_name passed - face_detector/yolov11
2024-12-22 16:55:04,154 - ERROR - 处理帧时出错: Invalid model_name passed - face_detector/yolov11
2024-12-22 16:55:04,315 - ERROR - 处理帧时出错: Invalid model_name passed - face_detector/yolov11
2024-12-22 16:55:04,491 - ERROR - 处理帧时出错: Invalid model_name passed - face_detector/yolov11
2024-12-22 16:55:04,667 - ERROR - 处理帧时出错: Invalid model_name passed - face_detector/yolov11
2024-12-22 16:55:04,796 - ERROR - 处理帧时出错: Invalid model_name passed - face_detector/yolov11
2024-12-22 16:55:05,003 - ERROR - 处理帧时出错: Invalid model_name passed - face_detector/yolov11
2024-12-22 16:55:05,130 - ERROR - 处理帧时出错: Invalid model_name passed - face_detector/yolov11
2024-12-22 16:55:05,309 - ERROR - 处理帧时出错: Invalid model_name passed - face_detector/yolov11
2024-12-22 16:55:05,468 - ERROR - 处理帧时出错: Invalid model_name passed - face_detector/yolov11
2024-12-22 16:55:05,644 - ERROR - 处理帧时出错: Invalid model_name passed - face_detector/yolov11
2024-12-22 16:55:05,820 - ERROR - 处理帧时出错: Invalid model_name passed - face_detector/yolov11
2024-12-22 16:55:05,980 - ERROR - 处理帧时出错: Invalid model_name passed - face_detector/yolov11
2024-12-22 16:55:06,156 - ERROR - 处理帧时出错: Invalid model_name passed - face_detector/yolov11
2024-12-22 16:55:06,314 - ERROR - 处理帧时出错: Invalid model_name passed - face_detector/yolov11
2024-12-22 16:55:06,491 - ERROR - 处理帧时出错: Invalid model_name passed - face_detector/yolov11
2024-12-22 16:55:06,668 - ERROR - 处理帧时出错: Invalid model_name passed - face_detector/yolov11
2024-12-22 16:55:06,796 - ERROR - 处理帧时出错: Invalid model_name passed - face_detector/yolov11
2024-12-22 16:55:07,004 - ERROR - 处理帧时出错: Invalid model_name passed - face_detector/yolov11
2024-12-22 16:55:07,131 - ERROR - 处理帧时出错: Invalid model_name passed - face_detector/yolov11
2024-12-22 16:55:07,308 - ERROR - 处理帧时出错: Invalid model_name passed - face_detector/yolov11
2024-12-22 16:55:07,468 - ERROR - 处理帧时出错: Invalid model_name passed - face_detector/yolov11
2024-12-22 16:55:07,644 - ERROR - 处理帧时出错: Invalid model_name passed - face_detector/yolov11
2024-12-22 16:55:07,820 - ERROR - 处理帧时出错: Invalid model_name passed - face_detector/yolov11
2024-12-22 16:55:07,978 - ERROR - 处理帧时出错: Invalid model_name passed - face_detector/yolov11
2024-12-22 16:55:08,156 - ERROR - 处理帧时出错: Invalid model_name passed - face_detector/yolov11
2024-12-22 16:55:08,316 - ERROR - 处理帧时出错: Invalid model_name passed - face_detector/yolov11
2024-12-22 16:55:08,500 - ERROR - 处理帧时出错: Invalid model_name passed - face_detector/yolov11
2024-12-22 16:55:08,654 - ERROR - 处理帧时出错: Invalid model_name passed - face_detector/yolov11
2024-12-22 16:55:08,795 - ERROR - 处理帧时出错: Invalid model_name passed - face_detector/yolov11
2024-12-22 16:55:09,003 - ERROR - 处理帧时出错: Invalid model_name passed - face_detector/yolov11
2024-12-22 16:55:09,131 - ERROR - 处理帧时出错: Invalid model_name passed - face_detector/yolov11
2024-12-22 16:55:09,308 - ERROR - 处理帧时出错: Invalid model_name passed - face_detector/yolov11
2024-12-22 16:55:09,468 - ERROR - 处理帧时出错: Invalid model_name passed - face_detector/yolov11
2024-12-22 16:55:09,644 - ERROR - 处理帧时出错: Invalid model_name passed - face_detector/yolov11
2024-12-22 16:55:09,820 - ERROR - 处理帧时出错: Invalid model_name passed - face_detector/yolov11
2024-12-22 16:55:09,981 - ERROR - 处理帧时出错: Invalid model_name passed - face_detector/yolov11
2024-12-22 16:55:10,154 - ERROR - 处理帧时出错: Invalid model_name passed - face_detector/yolov11
2024-12-22 16:55:10,316 - ERROR - 处理帧时出错: Invalid model_name passed - face_detector/yolov11
2024-12-22 16:55:10,491 - ERROR - 处理帧时出错: Invalid model_name passed - face_detector/yolov11
2024-12-22 16:55:10,651 - ERROR - 处理帧时出错: Invalid model_name passed - face_detector/yolov11
2024-12-22 16:55:10,795 - ERROR - 处理帧时出错: Invalid model_name passed - face_detector/yolov11
2024-12-23 12:56:22,811 - ERROR - 无法打开摄像头
2024-12-23 12:57:03,502 - ERROR - 处理帧时出错: name 'os' is not defined
2024-12-23 12:57:04,256 - ERROR - 处理帧时出错: name 'os' is not defined
2024-12-23 12:57:04,853 - ERROR - 处理帧时出错: name 'os' is not defined
2024-12-23 12:57:05,360 - ERROR - 处理帧时出错: name 'os' is not defined
2024-12-23 12:57:05,814 - ERROR - 处理帧时出错: name 'os' is not defined
2024-12-23 12:57:06,310 - ERROR - 处理帧时出错: name 'os' is not defined
2024-12-23 12:57:06,768 - ERROR - 处理帧时出错: name 'os' is not defined
2024-12-23 12:57:07,215 - ERROR - 处理帧时出错: name 'os' is not defined
2024-12-23 12:57:07,683 - ERROR - 处理帧时出错: name 'os' is not defined
2024-12-23 12:57:08,149 - ERROR - 处理帧时出错: name 'os' is not defined
2024-12-23 12:57:08,608 - ERROR - 处理帧时出错: name 'os' is not defined
2024-12-23 13:00:48,088 - ERROR - 处理帧时出错: 未找到权重文件：../pth/best_model_class7.h5
2024-12-23 13:00:48,694 - ERROR - 处理帧时出错: 未找到权重文件：../pth/best_model_class7.h5
2024-12-23 13:00:49,292 - ERROR - 处理帧时出错: 未找到权重文件：../pth/best_model_class7.h5
2024-12-23 13:00:49,821 - ERROR - 处理帧时出错: 未找到权重文件：../pth/best_model_class7.h5
2024-12-23 13:00:50,398 - ERROR - 处理帧时出错: 未找到权重文件：../pth/best_model_class7.h5
2024-12-23 13:00:50,918 - ERROR - 处理帧时出错: 未找到权重文件：../pth/best_model_class7.h5
2024-12-23 13:00:51,492 - ERROR - 处理帧时出错: 未找到权重文件：../pth/best_model_class7.h5
2024-12-23 13:00:52,027 - ERROR - 处理帧时出错: 未找到权重文件：../pth/best_model_class7.h5
2024-12-23 13:00:52,631 - ERROR - 处理帧时出错: 未找到权重文件：../pth/best_model_class7.h5
2024-12-23 13:00:53,239 - ERROR - 处理帧时出错: 未找到权重文件：../pth/best_model_class7.h5
2024-12-23 13:00:53,788 - ERROR - 处理帧时出错: 未找到权重文件：../pth/best_model_class7.h5
2024-12-23 13:00:54,369 - ERROR - 处理帧时出错: 未找到权重文件：../pth/best_model_class7.h5
2024-12-23 13:40:36,241 - ERROR - 处理帧时出错: OpenCV(4.10.0) d:\a\opencv-python\opencv-python\opencv\modules\imgproc\src\color.simd_helpers.hpp:92: error: (-2:Unspecified error) in function '__cdecl cv::impl::`anonymous-namespace'::CvtHelper<struct cv::impl::`anonymous namespace'::Set<3,4,-1>,struct cv::impl::A0x46dff480::Set<1,-1,-1>,struct cv::impl::A0x46dff480::Set<0,2,5>,4>::CvtHelper(const class cv::_InputArray &,const class cv::_OutputArray &,int)'
> Invalid number of channels in input image:
>     'VScn::contains(scn)'
> where
>     'scn' is 1

2024-12-23 13:40:36,515 - ERROR - 处理帧时出错: OpenCV(4.10.0) d:\a\opencv-python\opencv-python\opencv\modules\imgproc\src\color.simd_helpers.hpp:92: error: (-2:Unspecified error) in function '__cdecl cv::impl::`anonymous-namespace'::CvtHelper<struct cv::impl::`anonymous namespace'::Set<3,4,-1>,struct cv::impl::A0x46dff480::Set<1,-1,-1>,struct cv::impl::A0x46dff480::Set<0,2,5>,4>::CvtHelper(const class cv::_InputArray &,const class cv::_OutputArray &,int)'
> Invalid number of channels in input image:
>     'VScn::contains(scn)'
> where
>     'scn' is 1

2024-12-23 13:40:36,767 - ERROR - 处理帧时出错: OpenCV(4.10.0) d:\a\opencv-python\opencv-python\opencv\modules\imgproc\src\color.simd_helpers.hpp:92: error: (-2:Unspecified error) in function '__cdecl cv::impl::`anonymous-namespace'::CvtHelper<struct cv::impl::`anonymous namespace'::Set<3,4,-1>,struct cv::impl::A0x46dff480::Set<1,-1,-1>,struct cv::impl::A0x46dff480::Set<0,2,5>,4>::CvtHelper(const class cv::_InputArray &,const class cv::_OutputArray &,int)'
> Invalid number of channels in input image:
>     'VScn::contains(scn)'
> where
>     'scn' is 1

2024-12-23 13:40:36,935 - ERROR - 处理帧时出错: OpenCV(4.10.0) d:\a\opencv-python\opencv-python\opencv\modules\imgproc\src\color.simd_helpers.hpp:92: error: (-2:Unspecified error) in function '__cdecl cv::impl::`anonymous-namespace'::CvtHelper<struct cv::impl::`anonymous namespace'::Set<3,4,-1>,struct cv::impl::A0x46dff480::Set<1,-1,-1>,struct cv::impl::A0x46dff480::Set<0,2,5>,4>::CvtHelper(const class cv::_InputArray &,const class cv::_OutputArray &,int)'
> Invalid number of channels in input image:
>     'VScn::contains(scn)'
> where
>     'scn' is 1

2024-12-23 13:40:37,106 - ERROR - 处理帧时出错: OpenCV(4.10.0) d:\a\opencv-python\opencv-python\opencv\modules\imgproc\src\color.simd_helpers.hpp:92: error: (-2:Unspecified error) in function '__cdecl cv::impl::`anonymous-namespace'::CvtHelper<struct cv::impl::`anonymous namespace'::Set<3,4,-1>,struct cv::impl::A0x46dff480::Set<1,-1,-1>,struct cv::impl::A0x46dff480::Set<0,2,5>,4>::CvtHelper(const class cv::_InputArray &,const class cv::_OutputArray &,int)'
> Invalid number of channels in input image:
>     'VScn::contains(scn)'
> where
>     'scn' is 1

2024-12-23 13:40:37,272 - ERROR - 处理帧时出错: OpenCV(4.10.0) d:\a\opencv-python\opencv-python\opencv\modules\imgproc\src\color.simd_helpers.hpp:92: error: (-2:Unspecified error) in function '__cdecl cv::impl::`anonymous-namespace'::CvtHelper<struct cv::impl::`anonymous namespace'::Set<3,4,-1>,struct cv::impl::A0x46dff480::Set<1,-1,-1>,struct cv::impl::A0x46dff480::Set<0,2,5>,4>::CvtHelper(const class cv::_InputArray &,const class cv::_OutputArray &,int)'
> Invalid number of channels in input image:
>     'VScn::contains(scn)'
> where
>     'scn' is 1

2024-12-23 13:40:37,457 - ERROR - 处理帧时出错: OpenCV(4.10.0) d:\a\opencv-python\opencv-python\opencv\modules\imgproc\src\color.simd_helpers.hpp:92: error: (-2:Unspecified error) in function '__cdecl cv::impl::`anonymous-namespace'::CvtHelper<struct cv::impl::`anonymous namespace'::Set<3,4,-1>,struct cv::impl::A0x46dff480::Set<1,-1,-1>,struct cv::impl::A0x46dff480::Set<0,2,5>,4>::CvtHelper(const class cv::_InputArray &,const class cv::_OutputArray &,int)'
> Invalid number of channels in input image:
>     'VScn::contains(scn)'
> where
>     'scn' is 1

2024-12-23 13:40:37,679 - ERROR - 处理帧时出错: OpenCV(4.10.0) d:\a\opencv-python\opencv-python\opencv\modules\imgproc\src\color.simd_helpers.hpp:92: error: (-2:Unspecified error) in function '__cdecl cv::impl::`anonymous-namespace'::CvtHelper<struct cv::impl::`anonymous namespace'::Set<3,4,-1>,struct cv::impl::A0x46dff480::Set<1,-1,-1>,struct cv::impl::A0x46dff480::Set<0,2,5>,4>::CvtHelper(const class cv::_InputArray &,const class cv::_OutputArray &,int)'
> Invalid number of channels in input image:
>     'VScn::contains(scn)'
> where
>     'scn' is 1

2024-12-23 13:40:37,873 - ERROR - 处理帧时出错: OpenCV(4.10.0) d:\a\opencv-python\opencv-python\opencv\modules\imgproc\src\color.simd_helpers.hpp:92: error: (-2:Unspecified error) in function '__cdecl cv::impl::`anonymous-namespace'::CvtHelper<struct cv::impl::`anonymous namespace'::Set<3,4,-1>,struct cv::impl::A0x46dff480::Set<1,-1,-1>,struct cv::impl::A0x46dff480::Set<0,2,5>,4>::CvtHelper(const class cv::_InputArray &,const class cv::_OutputArray &,int)'
> Invalid number of channels in input image:
>     'VScn::contains(scn)'
> where
>     'scn' is 1

2024-12-23 13:40:38,134 - ERROR - 处理帧时出错: OpenCV(4.10.0) d:\a\opencv-python\opencv-python\opencv\modules\imgproc\src\color.simd_helpers.hpp:92: error: (-2:Unspecified error) in function '__cdecl cv::impl::`anonymous-namespace'::CvtHelper<struct cv::impl::`anonymous namespace'::Set<3,4,-1>,struct cv::impl::A0x46dff480::Set<1,-1,-1>,struct cv::impl::A0x46dff480::Set<0,2,5>,4>::CvtHelper(const class cv::_InputArray &,const class cv::_OutputArray &,int)'
> Invalid number of channels in input image:
>     'VScn::contains(scn)'
> where
>     'scn' is 1

2024-12-23 13:40:38,302 - ERROR - 处理帧时出错: OpenCV(4.10.0) d:\a\opencv-python\opencv-python\opencv\modules\imgproc\src\color.simd_helpers.hpp:92: error: (-2:Unspecified error) in function '__cdecl cv::impl::`anonymous-namespace'::CvtHelper<struct cv::impl::`anonymous namespace'::Set<3,4,-1>,struct cv::impl::A0x46dff480::Set<1,-1,-1>,struct cv::impl::A0x46dff480::Set<0,2,5>,4>::CvtHelper(const class cv::_InputArray &,const class cv::_OutputArray &,int)'
> Invalid number of channels in input image:
>     'VScn::contains(scn)'
> where
>     'scn' is 1

2024-12-23 13:40:38,469 - ERROR - 处理帧时出错: OpenCV(4.10.0) d:\a\opencv-python\opencv-python\opencv\modules\imgproc\src\color.simd_helpers.hpp:92: error: (-2:Unspecified error) in function '__cdecl cv::impl::`anonymous-namespace'::CvtHelper<struct cv::impl::`anonymous namespace'::Set<3,4,-1>,struct cv::impl::A0x46dff480::Set<1,-1,-1>,struct cv::impl::A0x46dff480::Set<0,2,5>,4>::CvtHelper(const class cv::_InputArray &,const class cv::_OutputArray &,int)'
> Invalid number of channels in input image:
>     'VScn::contains(scn)'
> where
>     'scn' is 1

2024-12-23 13:40:38,621 - ERROR - 处理帧时出错: OpenCV(4.10.0) d:\a\opencv-python\opencv-python\opencv\modules\imgproc\src\color.simd_helpers.hpp:92: error: (-2:Unspecified error) in function '__cdecl cv::impl::`anonymous-namespace'::CvtHelper<struct cv::impl::`anonymous namespace'::Set<3,4,-1>,struct cv::impl::A0x46dff480::Set<1,-1,-1>,struct cv::impl::A0x46dff480::Set<0,2,5>,4>::CvtHelper(const class cv::_InputArray &,const class cv::_OutputArray &,int)'
> Invalid number of channels in input image:
>     'VScn::contains(scn)'
> where
>     'scn' is 1

2024-12-23 13:40:38,777 - ERROR - 处理帧时出错: OpenCV(4.10.0) d:\a\opencv-python\opencv-python\opencv\modules\imgproc\src\color.simd_helpers.hpp:92: error: (-2:Unspecified error) in function '__cdecl cv::impl::`anonymous-namespace'::CvtHelper<struct cv::impl::`anonymous namespace'::Set<3,4,-1>,struct cv::impl::A0x46dff480::Set<1,-1,-1>,struct cv::impl::A0x46dff480::Set<0,2,5>,4>::CvtHelper(const class cv::_InputArray &,const class cv::_OutputArray &,int)'
> Invalid number of channels in input image:
>     'VScn::contains(scn)'
> where
>     'scn' is 1

2024-12-23 13:40:38,972 - ERROR - 处理帧时出错: OpenCV(4.10.0) d:\a\opencv-python\opencv-python\opencv\modules\imgproc\src\color.simd_helpers.hpp:92: error: (-2:Unspecified error) in function '__cdecl cv::impl::`anonymous-namespace'::CvtHelper<struct cv::impl::`anonymous namespace'::Set<3,4,-1>,struct cv::impl::A0x46dff480::Set<1,-1,-1>,struct cv::impl::A0x46dff480::Set<0,2,5>,4>::CvtHelper(const class cv::_InputArray &,const class cv::_OutputArray &,int)'
> Invalid number of channels in input image:
>     'VScn::contains(scn)'
> where
>     'scn' is 1

2024-12-23 13:40:39,126 - ERROR - 处理帧时出错: OpenCV(4.10.0) d:\a\opencv-python\opencv-python\opencv\modules\imgproc\src\color.simd_helpers.hpp:92: error: (-2:Unspecified error) in function '__cdecl cv::impl::`anonymous-namespace'::CvtHelper<struct cv::impl::`anonymous namespace'::Set<3,4,-1>,struct cv::impl::A0x46dff480::Set<1,-1,-1>,struct cv::impl::A0x46dff480::Set<0,2,5>,4>::CvtHelper(const class cv::_InputArray &,const class cv::_OutputArray &,int)'
> Invalid number of channels in input image:
>     'VScn::contains(scn)'
> where
>     'scn' is 1

2024-12-23 13:40:39,284 - ERROR - 处理帧时出错: OpenCV(4.10.0) d:\a\opencv-python\opencv-python\opencv\modules\imgproc\src\color.simd_helpers.hpp:92: error: (-2:Unspecified error) in function '__cdecl cv::impl::`anonymous-namespace'::CvtHelper<struct cv::impl::`anonymous namespace'::Set<3,4,-1>,struct cv::impl::A0x46dff480::Set<1,-1,-1>,struct cv::impl::A0x46dff480::Set<0,2,5>,4>::CvtHelper(const class cv::_InputArray &,const class cv::_OutputArray &,int)'
> Invalid number of channels in input image:
>     'VScn::contains(scn)'
> where
>     'scn' is 1

2024-12-23 13:40:39,465 - ERROR - 处理帧时出错: OpenCV(4.10.0) d:\a\opencv-python\opencv-python\opencv\modules\imgproc\src\color.simd_helpers.hpp:92: error: (-2:Unspecified error) in function '__cdecl cv::impl::`anonymous-namespace'::CvtHelper<struct cv::impl::`anonymous namespace'::Set<3,4,-1>,struct cv::impl::A0x46dff480::Set<1,-1,-1>,struct cv::impl::A0x46dff480::Set<0,2,5>,4>::CvtHelper(const class cv::_InputArray &,const class cv::_OutputArray &,int)'
> Invalid number of channels in input image:
>     'VScn::contains(scn)'
> where
>     'scn' is 1

2024-12-23 13:40:39,736 - ERROR - 处理帧时出错: OpenCV(4.10.0) d:\a\opencv-python\opencv-python\opencv\modules\imgproc\src\color.simd_helpers.hpp:92: error: (-2:Unspecified error) in function '__cdecl cv::impl::`anonymous-namespace'::CvtHelper<struct cv::impl::`anonymous namespace'::Set<3,4,-1>,struct cv::impl::A0x46dff480::Set<1,-1,-1>,struct cv::impl::A0x46dff480::Set<0,2,5>,4>::CvtHelper(const class cv::_InputArray &,const class cv::_OutputArray &,int)'
> Invalid number of channels in input image:
>     'VScn::contains(scn)'
> where
>     'scn' is 1

2024-12-23 13:40:39,971 - ERROR - 处理帧时出错: OpenCV(4.10.0) d:\a\opencv-python\opencv-python\opencv\modules\imgproc\src\color.simd_helpers.hpp:92: error: (-2:Unspecified error) in function '__cdecl cv::impl::`anonymous-namespace'::CvtHelper<struct cv::impl::`anonymous namespace'::Set<3,4,-1>,struct cv::impl::A0x46dff480::Set<1,-1,-1>,struct cv::impl::A0x46dff480::Set<0,2,5>,4>::CvtHelper(const class cv::_InputArray &,const class cv::_OutputArray &,int)'
> Invalid number of channels in input image:
>     'VScn::contains(scn)'
> where
>     'scn' is 1

2024-12-23 13:40:40,157 - ERROR - 处理帧时出错: OpenCV(4.10.0) d:\a\opencv-python\opencv-python\opencv\modules\imgproc\src\color.simd_helpers.hpp:92: error: (-2:Unspecified error) in function '__cdecl cv::impl::`anonymous-namespace'::CvtHelper<struct cv::impl::`anonymous namespace'::Set<3,4,-1>,struct cv::impl::A0x46dff480::Set<1,-1,-1>,struct cv::impl::A0x46dff480::Set<0,2,5>,4>::CvtHelper(const class cv::_InputArray &,const class cv::_OutputArray &,int)'
> Invalid number of channels in input image:
>     'VScn::contains(scn)'
> where
>     'scn' is 1

2024-12-23 13:40:40,321 - ERROR - 处理帧时出错: OpenCV(4.10.0) d:\a\opencv-python\opencv-python\opencv\modules\imgproc\src\color.simd_helpers.hpp:92: error: (-2:Unspecified error) in function '__cdecl cv::impl::`anonymous-namespace'::CvtHelper<struct cv::impl::`anonymous namespace'::Set<3,4,-1>,struct cv::impl::A0x46dff480::Set<1,-1,-1>,struct cv::impl::A0x46dff480::Set<0,2,5>,4>::CvtHelper(const class cv::_InputArray &,const class cv::_OutputArray &,int)'
> Invalid number of channels in input image:
>     'VScn::contains(scn)'
> where
>     'scn' is 1

2024-12-23 13:40:40,494 - ERROR - 处理帧时出错: OpenCV(4.10.0) d:\a\opencv-python\opencv-python\opencv\modules\imgproc\src\color.simd_helpers.hpp:92: error: (-2:Unspecified error) in function '__cdecl cv::impl::`anonymous-namespace'::CvtHelper<struct cv::impl::`anonymous namespace'::Set<3,4,-1>,struct cv::impl::A0x46dff480::Set<1,-1,-1>,struct cv::impl::A0x46dff480::Set<0,2,5>,4>::CvtHelper(const class cv::_InputArray &,const class cv::_OutputArray &,int)'
> Invalid number of channels in input image:
>     'VScn::contains(scn)'
> where
>     'scn' is 1

2024-12-23 14:11:50,380 - ERROR - 处理帧时出错: local variable 'image_batch' referenced before assignment
2024-12-23 14:11:50,827 - ERROR - 处理帧时出错: local variable 'image_batch' referenced before assignment
2024-12-23 14:11:51,024 - ERROR - 处理帧时出错: local variable 'image_batch' referenced before assignment
2024-12-23 14:11:51,284 - ERROR - 处理帧时出错: local variable 'image_batch' referenced before assignment
2024-12-23 14:11:51,554 - ERROR - 处理帧时出错: local variable 'image_batch' referenced before assignment
2024-12-23 14:11:51,796 - ERROR - 处理帧时出错: local variable 'image_batch' referenced before assignment
2024-12-23 14:11:52,044 - ERROR - 处理帧时出错: local variable 'image_batch' referenced before assignment
2024-12-23 14:11:52,213 - ERROR - 处理帧时出错: local variable 'image_batch' referenced before assignment
2024-12-23 14:11:52,374 - ERROR - 处理帧时出错: local variable 'image_batch' referenced before assignment
2024-12-23 14:11:52,560 - ERROR - 处理帧时出错: local variable 'image_batch' referenced before assignment
2024-12-23 14:11:52,739 - ERROR - 处理帧时出错: local variable 'image_batch' referenced before assignment
2024-12-23 14:11:53,028 - ERROR - 处理帧时出错: local variable 'image_batch' referenced before assignment
2024-12-23 14:11:53,319 - ERROR - 处理帧时出错: local variable 'image_batch' referenced before assignment
2024-12-23 14:11:53,584 - ERROR - 处理帧时出错: local variable 'image_batch' referenced before assignment
2024-12-23 14:11:53,832 - ERROR - 处理帧时出错: local variable 'image_batch' referenced before assignment
2024-12-23 14:11:54,071 - ERROR - 处理帧时出错: local variable 'image_batch' referenced before assignment
2024-12-23 14:11:54,341 - ERROR - 处理帧时出错: local variable 'image_batch' referenced before assignment
2024-12-23 14:11:54,616 - ERROR - 处理帧时出错: local variable 'image_batch' referenced before assignment
2024-12-23 14:11:54,895 - ERROR - 处理帧时出错: local variable 'image_batch' referenced before assignment
2024-12-23 15:05:40,933 - ERROR - 处理帧时出错: Input 0 of layer "sequential" is incompatible with the layer: expected shape=(None, 224, 224, 3), found shape=(224, 224, 3)
2024-12-23 15:05:41,243 - ERROR - 处理帧时出错: Input 0 of layer "sequential" is incompatible with the layer: expected shape=(None, 224, 224, 3), found shape=(224, 224, 3)
2024-12-23 15:05:41,504 - ERROR - 处理帧时出错: Input 0 of layer "sequential" is incompatible with the layer: expected shape=(None, 224, 224, 3), found shape=(224, 224, 3)
2024-12-23 15:05:41,788 - ERROR - 处理帧时出错: Input 0 of layer "sequential" is incompatible with the layer: expected shape=(None, 224, 224, 3), found shape=(224, 224, 3)
2024-12-23 15:05:42,038 - ERROR - 处理帧时出错: Input 0 of layer "sequential" is incompatible with the layer: expected shape=(None, 224, 224, 3), found shape=(224, 224, 3)
2024-12-23 15:05:42,304 - ERROR - 处理帧时出错: Input 0 of layer "sequential" is incompatible with the layer: expected shape=(None, 224, 224, 3), found shape=(224, 224, 3)
2024-12-23 15:05:42,598 - ERROR - 处理帧时出错: Input 0 of layer "sequential" is incompatible with the layer: expected shape=(None, 224, 224, 3), found shape=(224, 224, 3)
2024-12-23 15:05:42,847 - ERROR - 处理帧时出错: Input 0 of layer "sequential" is incompatible with the layer: expected shape=(None, 224, 224, 3), found shape=(224, 224, 3)
2024-12-23 15:05:43,325 - ERROR - 处理帧时出错: Input 0 of layer "sequential" is incompatible with the layer: expected shape=(None, 224, 224, 3), found shape=(224, 224, 3)
2024-12-23 15:05:43,586 - ERROR - 处理帧时出错: Input 0 of layer "sequential" is incompatible with the layer: expected shape=(None, 224, 224, 3), found shape=(224, 224, 3)
2024-12-23 15:05:43,849 - ERROR - 处理帧时出错: Input 0 of layer "sequential" is incompatible with the layer: expected shape=(None, 224, 224, 3), found shape=(224, 224, 3)
2024-12-23 15:05:44,105 - ERROR - 处理帧时出错: Input 0 of layer "sequential" is incompatible with the layer: expected shape=(None, 224, 224, 3), found shape=(224, 224, 3)
2024-12-23 15:31:49,478 - ERROR - 处理帧时出错: module 'keras.api._v2.keras.applications' has no attribute 'ConvNeXtTinyConvNeXtTiny'
2024-12-23 15:31:50,037 - ERROR - 处理帧时出错: module 'keras.api._v2.keras.applications' has no attribute 'ConvNeXtTinyConvNeXtTiny'
2024-12-23 15:31:50,310 - ERROR - 处理帧时出错: module 'keras.api._v2.keras.applications' has no attribute 'ConvNeXtTinyConvNeXtTiny'
2024-12-23 15:31:50,567 - ERROR - 处理帧时出错: module 'keras.api._v2.keras.applications' has no attribute 'ConvNeXtTinyConvNeXtTiny'
2024-12-23 15:31:50,845 - ERROR - 处理帧时出错: module 'keras.api._v2.keras.applications' has no attribute 'ConvNeXtTinyConvNeXtTiny'
2024-12-23 15:31:51,097 - ERROR - 处理帧时出错: module 'keras.api._v2.keras.applications' has no attribute 'ConvNeXtTinyConvNeXtTiny'
2024-12-23 15:31:51,375 - ERROR - 处理帧时出错: module 'keras.api._v2.keras.applications' has no attribute 'ConvNeXtTinyConvNeXtTiny'
2024-12-23 15:31:51,646 - ERROR - 处理帧时出错: module 'keras.api._v2.keras.applications' has no attribute 'ConvNeXtTinyConvNeXtTiny'
2024-12-23 15:31:51,868 - ERROR - 处理帧时出错: module 'keras.api._v2.keras.applications' has no attribute 'ConvNeXtTinyConvNeXtTiny'
2024-12-23 15:31:52,160 - ERROR - 处理帧时出错: module 'keras.api._v2.keras.applications' has no attribute 'ConvNeXtTinyConvNeXtTiny'
